Workbook

Sheet Per-Episode
A1: RoboMME — Per-Episode Outcomes (rows = task × policy grouped by suite, cols = episode)
A2: Suite | B2: Task | C2: Policy | D2: ep0 | E2: ep1 | F2: ep2 | G2: ep3 | H2: ep4 | I2: ep5 | J2: ep6 | K2: ep7 | L2: ep8 | M2: ep9 | N2: ep10 | O2: ep11 | P2: ep12 | Q2: ep13 | R2: ep14 | S2: ep15 | T2: ep16 | U2: ep17 | V2: ep18 | W2: ep19 | X2: ep20 | Y2: ep21 | Z2: ep22 | AA2: ep23 | AB2: ep24 | AC2: ep25 | AD2: ep26 | AE2: ep27 | AF2: ep28 | AG2: ep29 | AH2: ep30 | AI2: ep31 | AJ2: ep32 | AK2: ep33 | AL2: ep34 | AM2: ep35 | AN2: ep36 | AO2: ep37 | AP2: ep38 | AQ2: ep39 | AR2: ep40 | AS2: ep41 | AT2: ep42 | AU2: ep43 | AV2: ep44 | AW2: ep45 | AX2: ep46 | AY2: ep47 | AZ2: ep48 | BA2: ep49
A3: Counting | B3: BinFill | C3: hitsz | D3: success | E3: success | F3: success | G3: success | H3: success | I3: success | J3: success | K3: success | L3: success | M3: success | N3: fail | O3: success | P3: success | Q3: fail | R3: success | S3: fail | T3: fail | U3: fail | V3: success | W3: fail | X3: fail | Y3: fail | Z3: success | AA3: fail | AB3: fail | AC3: fail | AD3: success | AE3: fail | AF3: fail | AG3: success | AH3: fail | AI3: fail | AJ3: fail | AK3: success | AL3: fail | AM3: fail | AN3: fail | AO3: fail | AP3: fail | AQ3: fail | AR3: fail | AS3: fail | AT3: fail | AU3: fail | AV3: fail | AW3: fail | AX3: fail | AY3: fail | AZ3: fail | BA3: fail
A4: Counting | B4: BinFill | C4: thu | D4: success | E4: success | F4: success | G4: success | H4: success | I4: success | J4: success | K4: success | L4: fail | M4: success | N4: success | O4: success | P4: fail | Q4: success | R4: fail | S4: success | T4: success | U4: success | V4: success | W4: success | X4: success | Y4: success | Z4: success | AA4: fail | AB4: fail | AC4: fail | AD4: success | AE4: fail | AF4: success | AG4: fail | AH4: success | AI4: success | AJ4: fail | AK4: fail | AL4: fail | AM4: success | AN4: success | AO4: timeout | AP4: success | AQ4: success | AR4: success | AS4: fail | AT4: fail | AU4: success | AV4: success | AW4: fail | AX4: timeout | AY4: success | AZ4: success | BA4: fail
A5: Counting | B5: BinFill | C5: MemER
A6: Counting | B6: BinFill | C6: 512
A7: Counting | B7: PickXtimes | C7: hitsz | D7: fail | E7: success | F7: success | G7: success | H7: success | I7: success | J7: success | K7: success | L7: success | M7: success | N7: success | O7: fail | P7: success | Q7: fail | R7: success | S7: success | T7: success | U7: success | V7: success | W7: success | X7: success | Y7: success | Z7: success | AA7: success | AB7: success | AC7: success | AD7: success | AE7: success | AF7: success | AG7: success | AH7: success | AI7: success | AJ7: success | AK7: success | AL7: success | AM7: fail | AN7: success | AO7: fail | AP7: success | AQ7: success | AR7: success | AS7: fail | AT7: success | AU7: success | AV7: fail | AW7: fail | AX7: fail | AY7: fail | AZ7: success | BA7: success
A8: Counting | B8: PickXtimes | C8: thu | D8: success | E8: success | F8: success | G8: success | H8: success | I8: success | J8: success | K8: success | L8: fail | M8: success | N8: success | O8: success | P8: success | Q8: success | R8: success | S8: success | T8: success | U8: success | V8: success | W8: success | X8: success | Y8: success | Z8: success | AA8: success | AB8: success | AC8: success | AD8: success | AE8: success | AF8: success | AG8: success | AH8: success | AI8: success | AJ8: success | AK8: success | AL8: success | AM8: fail | AN8: success | AO8: success | AP8: success | AQ8: success | AR8: success | AS8: success | AT8: success | AU8: success | AV8: success | AW8: success | AX8: success | AY8: success | AZ8: success | BA8: success
A9: Counting | B9: PickXtimes | C9: MemER
A10: Counting | B10: PickXtimes | C10: 512
A11: Counting | B11: SwingXtimes | C11: hitsz | D11: fail | E11: success | F11: success | G11: success | H11: success | I11: success | J11: success | K11: success | L11: success | M11: success | N11: success | O11: success | P11: success | Q11: success | R11: fail | S11: success | T11: success | U11: fail | V11: success | W11: success | X11: success | Y11: success | Z11: success | AA11: success | AB11: success | AC11: success | AD11: fail | AE11: success | AF11: fail | AG11: fail | AH11: fail | AI11: fail | AJ11: success | AK11: fail | AL11: success | AM11: success | AN11: success | AO11: success | AP11: success | AQ11: success | AR11: success | AS11: success | AT11: success | AU11: fail | AV11: success | AW11: success | AX11: success | AY11: success | AZ11: fail | BA11: success
A12: Counting | B12: SwingXtimes | C12: thu | D12: success | E12: success | F12: success | G12: success | H12: success | I12: success | J12: success | K12: success | L12: success | M12: success | N12: success | O12: success | P12: success | Q12: success | R12: success | S12: success | T12: success | U12: success | V12: fail | W12: success | X12: success | Y12: success | Z12: success | AA12: success | AB12: success | AC12: success | AD12: success | AE12: success | AF12: success | AG12: success | AH12: success | AI12: success | AJ12: success | AK12: success | AL12: success | AM12: success | AN12: success | AO12: success | AP12: success | AQ12: success | AR12: success | AS12: success | AT12: success | AU12: success | AV12: fail | AW12: fail | AX12: success | AY12: success | AZ12: success | BA12: success
A13: Counting | B13: SwingXtimes | C13: MemER
A14: Counting | B14: SwingXtimes | C14: 512
A15: Counting | B15: StopCube | C15: hitsz | D15: success | E15: success | F15: fail | G15: fail | H15: success | I15: fail | J15: fail | K15: success | L15: fail | M15: fail | N15: fail | O15: fail | P15: success | Q15: success | R15: fail | S15: success | T15: success | U15: fail | V15: success | W15: fail | X15: success | Y15: success | Z15: success | AA15: success | AB15: success | AC15: success | AD15: fail | AE15: fail | AF15: fail | AG15: success | AH15: success | AI15: success | AJ15: fail | AK15: fail | AL15: success | AM15: fail | AN15: success | AO15: fail | AP15: fail | AQ15: fail | AR15: fail | AS15: fail | AT15: fail | AU15: fail | AV15: success | AW15: fail | AX15: success | AY15: fail | AZ15: fail | BA15: success
A16: Counting | B16: StopCube | C16: thu | D16: success | E16: success | F16: success | G16: fail | H16: success | I16: success | J16: fail | K16: success | L16: success | M16: success | N16: success | O16: fail | P16: success | Q16: success | R16: success | S16: success | T16: success | U16: fail | V16: success | W16: fail | X16: success | Y16: success | Z16: success | AA16: success | AB16: success | AC16: fail | AD16: success | AE16: fail | AF16: fail | AG16: success | AH16: success | AI16: success | AJ16: fail | AK16: fail | AL16: success | AM16: success | AN16: success | AO16: success | AP16: success | AQ16: success | AR16: success | AS16: success | AT16: success | AU16: fail | AV16: success | AW16: success | AX16: success | AY16: fail | AZ16: success | BA16: fail
A17: Counting | B17: StopCube | C17: MemER
A18: Counting | B18: StopCube | C18: 512
A19: Permanence | B19: VideoUnmask | C19: hitsz | D19: fail | E19: success | F19: success | G19: success | H19: fail | I19: fail | J19: success | K19: fail | L19: success | M19: fail | N19: fail | O19: fail | P19: success | Q19: fail | R19: fail | S19: fail | T19: fail | U19: success | V19: fail | W19: fail | X19: fail | Y19: fail | Z19: fail | AA19: fail | AB19: success | AC19: fail | AD19: fail | AE19: fail | AF19: success | AG19: fail | AH19: fail | AI19: fail | AJ19: fail | AK19: fail | AL19: fail | AM19: fail | AN19: fail | AO19: fail | AP19: fail | AQ19: fail | AR19: fail | AS19: fail | AT19: fail | AU19: fail | AV19: fail | AW19: fail | AX19: fail | AY19: fail | AZ19: fail | BA19: fail
A20: Permanence | B20: VideoUnmask | C20: thu | D20: fail | E20: fail | F20: success | G20: success | H20: fail | I20: fail | J20: success | K20: fail | L20: success | M20: success | N20: fail | O20: fail | P20: fail | Q20: fail | R20: fail | S20: fail | T20: fail | U20: success | V20: fail | W20: fail | X20: fail | Y20: fail | Z20: fail | AA20: fail | AB20: success | AC20: fail | AD20: success | AE20: fail | AF20: success | AG20: fail | AH20: fail | AI20: fail | AJ20: fail | AK20: fail | AL20: fail | AM20: success | AN20: fail | AO20: fail | AP20: fail | AQ20: fail | AR20: fail | AS20: fail | AT20: fail | AU20: fail | AV20: fail | AW20: fail | AX20: fail | AY20: fail | AZ20: fail | BA20: fail
A21: Permanence | B21: VideoUnmask | C21: MemER
A22: Permanence | B22: VideoUnmask | C22: 512
A23: Permanence | B23: ButtonUnmask | C23: hitsz | D23: fail | E23: fail | F23: success | G23: fail | H23: fail | I23: fail | J23: fail | K23: fail | L23: fail | M23: success | N23: fail | O23: fail | P23: fail | Q23: fail | R23: fail | S23: fail | T23: fail | U23: fail | V23: success | W23: fail | X23: fail | Y23: fail | Z23: fail | AA23: fail | AB23: fail | AC23: fail | AD23: fail | AE23: fail | AF23: fail | AG23: success | AH23: fail | AI23: fail | AJ23: fail | AK23: fail | AL23: fail | AM23: fail | AN23: fail | AO23: fail | AP23: success | AQ23: timeout | AR23: success | AS23: fail | AT23: fail | AU23: fail | AV23: fail | AW23: fail | AX23: fail | AY23: fail | AZ23: fail | BA23: fail
A24: Permanence | B24: ButtonUnmask | C24: thu | D24: fail | E24: success | F24: fail | G24: timeout | H24: fail | I24: fail | J24: fail | K24: success | L24: success | M24: fail | N24: fail | O24: fail | P24: fail | Q24: success | R24: fail | S24: fail | T24: fail | U24: success | V24: success | W24: fail | X24: fail | Y24: fail | Z24: fail | AA24: fail | AB24: fail | AC24: fail | AD24: fail | AE24: fail | AF24: fail | AG24: fail | AH24: fail | AI24: fail | AJ24: fail | AK24: fail | AL24: fail | AM24: fail | AN24: timeout | AO24: timeout | AP24: fail | AQ24: fail | AR24: success | AS24: fail | AT24: fail | AU24: fail | AV24: fail | AW24: fail | AX24: fail | AY24: fail | AZ24: fail | BA24: fail
A25: Permanence | B25: ButtonUnmask | C25: MemER
A26: Permanence | B26: ButtonUnmask | C26: 512
A27: Permanence | B27: VideoUnmaskSwap | C27: hitsz | D27: fail | E27: fail | F27: fail | G27: fail | H27: fail | I27: fail | J27: success | K27: fail | L27: fail | M27: fail | N27: fail | O27: fail | P27: fail | Q27: success | R27: success | S27: success | T27: success | U27: success | V27: fail | W27: fail | X27: fail | Y27: success | Z27: success | AA27: success | AB27: fail | AC27: fail | AD27: fail | AE27: success | AF27: fail | AG27: success | AH27: fail | AI27: fail | AJ27: fail | AK27: fail | AL27: success | AM27: fail | AN27: fail | AO27: fail | AP27: fail | AQ27: fail | AR27: fail | AS27: success | AT27: fail | AU27: fail | AV27: fail | AW27: fail | AX27: success | AY27: fail | AZ27: fail | BA27: fail
A28: Permanence | B28: VideoUnmaskSwap | C28: thu | D28: fail | E28: fail | F28: fail | G28: fail | H28: fail | I28: fail | J28: fail | K28: fail | L28: fail | M28: fail | N28: success | O28: fail | P28: fail | Q28: success | R28: fail | S28: success | T28: fail | U28: success | V28: fail | W28: fail | X28: fail | Y28: success | Z28: success | AA28: fail | AB28: fail | AC28: fail | AD28: fail | AE28: fail | AF28: fail | AG28: success | AH28: fail | AI28: fail | AJ28: fail | AK28: fail | AL28: success | AM28: fail | AN28: fail | AO28: fail | AP28: fail | AQ28: fail | AR28: fail | AS28: success | AT28: fail | AU28: fail | AV28: fail | AW28: fail | AX28: fail | AY28: fail | AZ28: fail | BA28: fail
A29: Permanence | B29: VideoUnmaskSwap | C29: MemER
A30: Permanence | B30: VideoUnmaskSwap | C30: 512
A31: Permanence | B31: ButtonUnmaskSwap | C31: hitsz | D31: timeout | E31: timeout | F31: fail | G31: fail | H31: fail | I31: timeout | J31: success | K31: timeout | L31: fail | M31: success | N31: success | O31: fail | P31: fail | Q31: fail | R31: timeout | S31: success | T31: timeout | U31: fail | V31: fail | W31: timeout | X31: fail | Y31: fail | Z31: success | AA31: fail | AB31: timeout | AC31: success | AD31: fail | AE31: timeout | AF31: fail | AG31: fail | AH31: fail | AI31: fail | AJ31: fail | AK31: fail | AL31: timeout | AM31: timeout | AN31: fail | AO31: timeout | AP31: fail | AQ31: fail | AR31: fail | AS31: timeout | AT31: fail | AU31: fail | AV31: fail | AW31: timeout | AX31: timeout | AY31: timeout | AZ31: timeout | BA31: fail
A32: Permanence | B32: ButtonUnmaskSwap | C32: thu | D32: timeout | E32: timeout | F32: fail | G32: fail | H32: fail | I32: fail | J32: success | K32: fail | L32: fail | M32: success | N32: success | O32: fail | P32: fail | Q32: fail | R32: fail | S32: success | T32: timeout | U32: fail | V32: fail | W32: timeout | X32: fail | Y32: success | Z32: success | AA32: fail | AB32: success | AC32: fail | AD32: fail | AE32: success | AF32: fail | AG32: fail | AH32: fail | AI32: fail | AJ32: fail | AK32: fail | AL32: fail | AM32: fail | AN32: fail | AO32: success | AP32: fail | AQ32: fail | AR32: fail | AS32: fail | AT32: fail | AU32: fail | AV32: success | AW32: timeout | AX32: timeout | AY32: fail | AZ32: fail | BA32: timeout
A33: Permanence | B33: ButtonUnmaskSwap | C33: MemER
A34: Permanence | B34: ButtonUnmaskSwap | C34: 512
A35: Reference | B35: PickHighlight | C35: hitsz | D35: fail | E35: success | F35: fail | G35: success | H35: success | I35: fail | J35: fail | K35: fail | L35: success | M35: fail | N35: fail | O35: fail | P35: fail | Q35: fail | R35: fail | S35: fail | T35: fail | U35: fail | V35: fail | W35: fail | X35: fail | Y35: fail | Z35: fail | AA35: fail | AB35: fail | AC35: success | AD35: fail | AE35: success | AF35: fail | AG35: fail | AH35: fail | AI35: fail | AJ35: fail | AK35: fail | AL35: fail | AM35: fail | AN35: fail | AO35: fail | AP35: fail | AQ35: fail | AR35: fail | AS35: fail | AT35: fail | AU35: fail | AV35: fail | AW35: timeout | AX35: fail | AY35: fail | AZ35: fail | BA35: fail
A36: Reference | B36: PickHighlight | C36: thu | D36: fail | E36: fail | F36: fail | G36: fail | H36: success | I36: fail | J36: success | K36: fail | L36: success | M36: fail | N36: fail | O36: fail | P36: fail | Q36: fail | R36: fail | S36: fail | T36: success | U36: fail | V36: fail | W36: fail | X36: success | Y36: fail | Z36: fail | AA36: fail | AB36: fail | AC36: fail | AD36: fail | AE36: success | AF36: timeout | AG36: success | AH36: fail | AI36: fail | AJ36: fail | AK36: fail | AL36: fail | AM36: fail | AN36: timeout | AO36: fail | AP36: fail | AQ36: fail | AR36: fail | AS36: success | AT36: fail | AU36: fail | AV36: timeout | AW36: fail | AX36: fail | AY36: fail | AZ36: fail | BA36: fail
A37: Reference | B37: PickHighlight | C37: MemER
A38: Reference | B38: PickHighlight | C38: 512
A39: Reference | B39: VideoRepick | C39: hitsz | D39: fail | E39: fail | F39: fail | G39: fail | H39: fail | I39: success | J39: fail | K39: fail | L39: success | M39: success | N39: success | O39: fail | P39: success | Q39: fail | R39: fail | S39: success | T39: fail | U39: fail | V39: fail | W39: fail | X39: success | Y39: fail | Z39: success | AA39: success | AB39: fail | AC39: success | AD39: success | AE39: success | AF39: fail | AG39: fail | AH39: fail | AI39: success | AJ39: fail | AK39: success | AL39: fail | AM39: fail | AN39: fail | AO39: fail | AP39: fail | AQ39: fail | AR39: fail | AS39: success | AT39: fail | AU39: fail | AV39: success | AW39: fail | AX39: fail | AY39: fail | AZ39: fail | BA39: fail
A40: Reference | B40: VideoRepick | C40: thu | D40: success | E40: success | F40: fail | G40: fail | H40: fail | I40: fail | J40: fail | K40: fail | L40: fail | M40: fail | N40: success | O40: fail | P40: success | Q40: fail | R40: fail | S40: success | T40: success | U40: fail | V40: fail | W40: fail | X40: fail | Y40: success | Z40: success | AA40: fail | AB40: fail | AC40: fail | AD40: fail | AE40: fail | AF40: fail | AG40: fail | AH40: success | AI40: fail | AJ40: fail | AK40: fail | AL40: success | AM40: fail | AN40: fail | AO40: fail | AP40: fail | AQ40: fail | AR40: fail | AS40: fail | AT40: success | AU40: fail | AV40: success | AW40: fail | AX40: success | AY40: fail | AZ40: fail | BA40: fail
...

Sheet Summary
A1: Summary — Success / Fail by task & suite
A2: Suite | B2: Task | C2: Policy | D2: Success | E2: Fail | F2: Timeout | G2: SceneErr | H2: Episodes | I2: Success Rate
A3: Counting | B3: BinFill | C3: hitsz | D3: =IF(COUNTA('Per-Episode'!$D$3:$BA$3)=0,"",COUNTIF('Per-Episode'!$D$3:$BA$3,"success")) | E3: =IF(COUNTA('Per-Episode'!$D$3:$BA$3)=0,"",COUNTIF('Per-Episode'!$D$3:$BA$3,"fail")) | F3: =IF(COUNTA('Per-Episode'!$D$3:$BA$3)=0,"",COUNTIF('Per-Episode'!$D$3:$BA$3,"timeout")) | G3: =IF(COUNTA('Per-Episode'!$D$3:$BA$3)=0,"",COUNTIF('Per-Episode'!$D$3:$BA$3,"scene_error")) | H3: =IF(COUNTA('Per-Episode'!$D$3:$BA$3)=0,"",COUNTA('Per-Episode'!$D$3:$BA$3)) | I3: =IF($H$3="","",$D$3/$H$3)
A4: Counting | B4: BinFill | C4: thu | D4: 33 | E4: 15 | F4: 2 | G4: 0 | H4: 50 | I4: 0.66
A5: Counting | B5: BinFill | C5: MemER | D5: =IF(COUNTA('Per-Episode'!$D$5:$BA$5)=0,"",COUNTIF('Per-Episode'!$D$5:$BA$5,"success")) | E5: =IF(COUNTA('Per-Episode'!$D$5:$BA$5)=0,"",COUNTIF('Per-Episode'!$D$5:$BA$5,"fail")) | F5: =IF(COUNTA('Per-Episode'!$D$5:$BA$5)=0,"",COUNTIF('Per-Episode'!$D$5:$BA$5,"timeout")) | G5: =IF(COUNTA('Per-Episode'!$D$5:$BA$5)=0,"",COUNTIF('Per-Episode'!$D$5:$BA$5,"scene_error")) | H5: =IF(COUNTA('Per-Episode'!$D$5:$BA$5)=0,"",COUNTA('Per-Episode'!$D$5:$BA$5)) | I5: =IF($H$5="","",$D$5/$H$5)
A6: Counting | B6: BinFill | C6: 512 | D6: =IF(COUNTA('Per-Episode'!$D$6:$BA$6)=0,"",COUNTIF('Per-Episode'!$D$6:$BA$6,"success")) | E6: =IF(COUNTA('Per-Episode'!$D$6:$BA$6)=0,"",COUNTIF('Per-Episode'!$D$6:$BA$6,"fail")) | F6: =IF(COUNTA('Per-Episode'!$D$6:$BA$6)=0,"",COUNTIF('Per-Episode'!$D$6:$BA$6,"timeout")) | G6: =IF(COUNTA('Per-Episode'!$D$6:$BA$6)=0,"",COUNTIF('Per-Episode'!$D$6:$BA$6,"scene_error")) | H6: =IF(COUNTA('Per-Episode'!$D$6:$BA$6)=0,"",COUNTA('Per-Episode'!$D$6:$BA$6)) | I6: =IF($H$6="","",$D$6/$H$6)
A7: Counting | B7: PickXtimes | C7: hitsz | D7: =IF(COUNTA('Per-Episode'!$D$7:$BA$7)=0,"",COUNTIF('Per-Episode'!$D$7:$BA$7,"success")) | E7: =IF(COUNTA('Per-Episode'!$D$7:$BA$7)=0,"",COUNTIF('Per-Episode'!$D$7:$BA$7,"fail")) | F7: =IF(COUNTA('Per-Episode'!$D$7:$BA$7)=0,"",COUNTIF('Per-Episode'!$D$7:$BA$7,"timeout")) | G7: =IF(COUNTA('Per-Episode'!$D$7:$BA$7)=0,"",COUNTIF('Per-Episode'!$D$7:$BA$7,"scene_error")) | H7: =IF(COUNTA('Per-Episode'!$D$7:$BA$7)=0,"",COUNTA('Per-Episode'!$D$7:$BA$7)) | I7: =IF($H$7="","",$D$7/$H$7)
A8: Counting | B8: PickXtimes | C8: thu | D8: 48 | E8: 2 | F8: 0 | G8: 0 | H8: 50 | I8: 0.96
A9: Counting | B9: PickXtimes | C9: MemER | D9: =IF(COUNTA('Per-Episode'!$D$9:$BA$9)=0,"",COUNTIF('Per-Episode'!$D$9:$BA$9,"success")) | E9: =IF(COUNTA('Per-Episode'!$D$9:$BA$9)=0,"",COUNTIF('Per-Episode'!$D$9:$BA$9,"fail")) | F9: =IF(COUNTA('Per-Episode'!$D$9:$BA$9)=0,"",COUNTIF('Per-Episode'!$D$9:$BA$9,"timeout")) | G9: =IF(COUNTA('Per-Episode'!$D$9:$BA$9)=0,"",COUNTIF('Per-Episode'!$D$9:$BA$9,"scene_error")) | H9: =IF(COUNTA('Per-Episode'!$D$9:$BA$9)=0,"",COUNTA('Per-Episode'!$D$9:$BA$9)) | I9: =IF($H$9="","",$D$9/$H$9)
A10: Counting | B10: PickXtimes | C10: 512 | D10: =IF(COUNTA('Per-Episode'!$D$10:$BA$10)=0,"",COUNTIF('Per-Episode'!$D$10:$BA$10,"success")) | E10: =IF(COUNTA('Per-Episode'!$D$10:$BA$10)=0,"",COUNTIF('Per-Episode'!$D$10:$BA$10,"fail")) | F10: =IF(COUNTA('Per-Episode'!$D$10:$BA$10)=0,"",COUNTIF('Per-Episode'!$D$10:$BA$10,"timeout")) | G10: =IF(COUNTA('Per-Episode'!$D$10:$BA$10)=0,"",COUNTIF('Per-Episode'!$D$10:$BA$10,"scene_error")) | H10: =IF(COUNTA('Per-Episode'!$D$10:$BA$10)=0,"",COUNTA('Per-Episode'!$D$10:$BA$10)) | I10: =IF($H$10="","",$D$10/$H$10)
A11: Counting | B11: SwingXtimes | C11: hitsz | D11: =IF(COUNTA('Per-Episode'!$D$11:$BA$11)=0,"",COUNTIF('Per-Episode'!$D$11:$BA$11,"success")) | E11: =IF(COUNTA('Per-Episode'!$D$11:$BA$11)=0,"",COUNTIF('Per-Episode'!$D$11:$BA$11,"fail")) | F11: =IF(COUNTA('Per-Episode'!$D$11:$BA$11)=0,"",COUNTIF('Per-Episode'!$D$11:$BA$11,"timeout")) | G11: =IF(COUNTA('Per-Episode'!$D$11:$BA$11)=0,"",COUNTIF('Per-Episode'!$D$11:$BA$11,"scene_error")) | H11: =IF(COUNTA('Per-Episode'!$D$11:$BA$11)=0,"",COUNTA('Per-Episode'!$D$11:$BA$11)) | I11: =IF($H$11="","",$D$11/$H$11)
A12: Counting | B12: SwingXtimes | C12: thu | D12: 47 | E12: 3 | F12: 0 | G12: 0 | H12: 50 | I12: 0.94
A13: Counting | B13: SwingXtimes | C13: MemER | D13: =IF(COUNTA('Per-Episode'!$D$13:$BA$13)=0,"",COUNTIF('Per-Episode'!$D$13:$BA$13,"success")) | E13: =IF(COUNTA('Per-Episode'!$D$13:$BA$13)=0,"",COUNTIF('Per-Episode'!$D$13:$BA$13,"fail")) | F13: =IF(COUNTA('Per-Episode'!$D$13:$BA$13)=0,"",COUNTIF('Per-Episode'!$D$13:$BA$13,"timeout")) | G13: =IF(COUNTA('Per-Episode'!$D$13:$BA$13)=0,"",COUNTIF('Per-Episode'!$D$13:$BA$13,"scene_error")) | H13: =IF(COUNTA('Per-Episode'!$D$13:$BA$13)=0,"",COUNTA('Per-Episode'!$D$13:$BA$13)) | I13: =IF($H$13="","",$D$13/$H$13)
A14: Counting | B14: SwingXtimes | C14: 512 | D14: =IF(COUNTA('Per-Episode'!$D$14:$BA$14)=0,"",COUNTIF('Per-Episode'!$D$14:$BA$14,"success")) | E14: =IF(COUNTA('Per-Episode'!$D$14:$BA$14)=0,"",COUNTIF('Per-Episode'!$D$14:$BA$14,"fail")) | F14: =IF(COUNTA('Per-Episode'!$D$14:$BA$14)=0,"",COUNTIF('Per-Episode'!$D$14:$BA$14,"timeout")) | G14: =IF(COUNTA('Per-Episode'!$D$14:$BA$14)=0,"",COUNTIF('Per-Episode'!$D$14:$BA$14,"scene_error")) | H14: =IF(COUNTA('Per-Episode'!$D$14:$BA$14)=0,"",COUNTA('Per-Episode'!$D$14:$BA$14)) | I14: =IF($H$14="","",$D$14/$H$14)
A15: Counting | B15: StopCube | C15: hitsz | D15: =IF(COUNTA('Per-Episode'!$D$15:$BA$15)=0,"",COUNTIF('Per-Episode'!$D$15:$BA$15,"success")) | E15: =IF(COUNTA('Per-Episode'!$D$15:$BA$15)=0,"",COUNTIF('Per-Episode'!$D$15:$BA$15,"fail")) | F15: =IF(COUNTA('Per-Episode'!$D$15:$BA$15)=0,"",COUNTIF('Per-Episode'!$D$15:$BA$15,"timeout")) | G15: =IF(COUNTA('Per-Episode'!$D$15:$BA$15)=0,"",COUNTIF('Per-Episode'!$D$15:$BA$15,"scene_error")) | H15: =IF(COUNTA('Per-Episode'!$D$15:$BA$15)=0,"",COUNTA('Per-Episode'!$D$15:$BA$15)) | I15: =IF($H$15="","",$D$15/$H$15)
A16: Counting | B16: StopCube | C16: thu | D16: 37 | E16: 13 | F16: 0 | G16: 0 | H16: 50 | I16: 0.74
A17: Counting | B17: StopCube | C17: MemER | D17: =IF(COUNTA('Per-Episode'!$D$17:$BA$17)=0,"",COUNTIF('Per-Episode'!$D$17:$BA$17,"success")) | E17: =IF(COUNTA('Per-Episode'!$D$17:$BA$17)=0,"",COUNTIF('Per-Episode'!$D$17:$BA$17,"fail")) | F17: =IF(COUNTA('Per-Episode'!$D$17:$BA$17)=0,"",COUNTIF('Per-Episode'!$D$17:$BA$17,"timeout")) | G17: =IF(COUNTA('Per-Episode'!$D$17:$BA$17)=0,"",COUNTIF('Per-Episode'!$D$17:$BA$17,"scene_error")) | H17: =IF(COUNTA('Per-Episode'!$D$17:$BA$17)=0,"",COUNTA('Per-Episode'!$D$17:$BA$17)) | I17: =IF($H$17="","",$D$17/$H$17)
A18: Counting | B18: StopCube | C18: 512 | D18: =IF(COUNTA('Per-Episode'!$D$18:$BA$18)=0,"",COUNTIF('Per-Episode'!$D$18:$BA$18,"success")) | E18: =IF(COUNTA('Per-Episode'!$D$18:$BA$18)=0,"",COUNTIF('Per-Episode'!$D$18:$BA$18,"fail")) | F18: =IF(COUNTA('Per-Episode'!$D$18:$BA$18)=0,"",COUNTIF('Per-Episode'!$D$18:$BA$18,"timeout")) | G18: =IF(COUNTA('Per-Episode'!$D$18:$BA$18)=0,"",COUNTIF('Per-Episode'!$D$18:$BA$18,"scene_error")) | H18: =IF(COUNTA('Per-Episode'!$D$18:$BA$18)=0,"",COUNTA('Per-Episode'!$D$18:$BA$18)) | I18: =IF($H$18="","",$D$18/$H$18)
A19: Counting — Subtotal | C19: hitsz | D19: =IF(SUM($H$3,$H$7,$H$11,$H$15)=0,"",SUM($D$3,$D$7,$D$11,$D$15)) | E19: =IF(SUM($H$3,$H$7,$H$11,$H$15)=0,"",SUM($E$3,$E$7,$E$11,$E$15)) | F19: =IF(SUM($H$3,$H$7,$H$11,$H$15)=0,"",SUM($F$3,$F$7,$F$11,$F$15)) | G19: =IF(SUM($H$3,$H$7,$H$11,$H$15)=0,"",SUM($G$3,$G$7,$G$11,$G$15)) | H19: =IF(SUM($H$3,$H$7,$H$11,$H$15)=0,"",SUM($H$3,$H$7,$H$11,$H$15)) | I19: =IF($H$19="","",$D$19/$H$19)
A20: Counting — Subtotal | C20: thu | D20: 165 | E20: 33 | F20: 2 | G20: 0 | H20: 200 | I20: 0.825
A21: Counting — Subtotal | C21: MemER | D21: =IF(SUM($H$5,$H$9,$H$13,$H$17)=0,"",SUM($D$5,$D$9,$D$13,$D$17)) | E21: =IF(SUM($H$5,$H$9,$H$13,$H$17)=0,"",SUM($E$5,$E$9,$E$13,$E$17)) | F21: =IF(SUM($H$5,$H$9,$H$13,$H$17)=0,"",SUM($F$5,$F$9,$F$13,$F$17)) | G21: =IF(SUM($H$5,$H$9,$H$13,$H$17)=0,"",SUM($G$5,$G$9,$G$13,$G$17)) | H21: =IF(SUM($H$5,$H$9,$H$13,$H$17)=0,"",SUM($H$5,$H$9,$H$13,$H$17)) | I21: =IF($H$21="","",$D$21/$H$21)
A22: Counting — Subtotal | C22: 512 | D22: =IF(SUM($H$6,$H$10,$H$14,$H$18)=0,"",SUM($D$6,$D$10,$D$14,$D$18)) | E22: =IF(SUM($H$6,$H$10,$H$14,$H$18)=0,"",SUM($E$6,$E$10,$E$14,$E$18)) | F22: =IF(SUM($H$6,$H$10,$H$14,$H$18)=0,"",SUM($F$6,$F$10,$F$14,$F$18)) | G22: =IF(SUM($H$6,$H$10,$H$14,$H$18)=0,"",SUM($G$6,$G$10,$G$14,$G$18)) | H22: =IF(SUM($H$6,$H$10,$H$14,$H$18)=0,"",SUM($H$6,$H$10,$H$14,$H$18)) | I22: =IF($H$22="","",$D$22/$H$22)
A23: Permanence | B23: VideoUnmask | C23: hitsz | D23: =IF(COUNTA('Per-Episode'!$D$19:$BA$19)=0,"",COUNTIF('Per-Episode'!$D$19:$BA$19,"success")) | E23: =IF(COUNTA('Per-Episode'!$D$19:$BA$19)=0,"",COUNTIF('Per-Episode'!$D$19:$BA$19,"fail")) | F23: =IF(COUNTA('Per-Episode'!$D$19:$BA$19)=0,"",COUNTIF('Per-Episode'!$D$19:$BA$19,"timeout")) | G23: =IF(COUNTA('Per-Episode'!$D$19:$BA$19)=0,"",COUNTIF('Per-Episode'!$D$19:$BA$19,"scene_error")) | H23: =IF(COUNTA('Per-Episode'!$D$19:$BA$19)=0,"",COUNTA('Per-Episode'!$D$19:$BA$19)) | I23: =IF($H$23="","",$D$23/$H$23)
A24: Permanence | B24: VideoUnmask | C24: thu | D24: 10 | E24: 40 | F24: 0 | G24: 0 | H24: 50 | I24: 0.2
A25: Permanence | B25: VideoUnmask | C25: MemER | D25: =IF(COUNTA('Per-Episode'!$D$21:$BA$21)=0,"",COUNTIF('Per-Episode'!$D$21:$BA$21,"success")) | E25: =IF(COUNTA('Per-Episode'!$D$21:$BA$21)=0,"",COUNTIF('Per-Episode'!$D$21:$BA$21,"fail")) | F25: =IF(COUNTA('Per-Episode'!$D$21:$BA$21)=0,"",COUNTIF('Per-Episode'!$D$21:$BA$21,"timeout")) | G25: =IF(COUNTA('Per-Episode'!$D$21:$BA$21)=0,"",COUNTIF('Per-Episode'!$D$21:$BA$21,"scene_error")) | H25: =IF(COUNTA('Per-Episode'!$D$21:$BA$21)=0,"",COUNTA('Per-Episode'!$D$21:$BA$21)) | I25: =IF($H$25="","",$D$25/$H$25)
A26: Permanence | B26: VideoUnmask | C26: 512 | D26: =IF(COUNTA('Per-Episode'!$D$22:$BA$22)=0,"",COUNTIF('Per-Episode'!$D$22:$BA$22,"success")) | E26: =IF(COUNTA('Per-Episode'!$D$22:$BA$22)=0,"",COUNTIF('Per-Episode'!$D$22:$BA$22,"fail")) | F26: =IF(COUNTA('Per-Episode'!$D$22:$BA$22)=0,"",COUNTIF('Per-Episode'!$D$22:$BA$22,"timeout")) | G26: =IF(COUNTA('Per-Episode'!$D$22:$BA$22)=0,"",COUNTIF('Per-Episode'!$D$22:$BA$22,"scene_error")) | H26: =IF(COUNTA('Per-Episode'!$D$22:$BA$22)=0,"",COUNTA('Per-Episode'!$D$22:$BA$22)) | I26: =IF($H$26="","",$D$26/$H$26)
A27: Permanence | B27: ButtonUnmask | C27: hitsz | D27: =IF(COUNTA('Per-Episode'!$D$23:$BA$23)=0,"",COUNTIF('Per-Episode'!$D$23:$BA$23,"success")) | E27: =IF(COUNTA('Per-Episode'!$D$23:$BA$23)=0,"",COUNTIF('Per-Episode'!$D$23:$BA$23,"fail")) | F27: =IF(COUNTA('Per-Episode'!$D$23:$BA$23)=0,"",COUNTIF('Per-Episode'!$D$23:$BA$23,"timeout")) | G27: =IF(COUNTA('Per-Episode'!$D$23:$BA$23)=0,"",COUNTIF('Per-Episode'!$D$23:$BA$23,"scene_error")) | H27: =IF(COUNTA('Per-Episode'!$D$23:$BA$23)=0,"",COUNTA('Per-Episode'!$D$23:$BA$23)) | I27: =IF($H$27="","",$D$27/$H$27)
A28: Permanence | B28: ButtonUnmask | C28: thu | D28: 7 | E28: 40 | F28: 3 | G28: 0 | H28: 50 | I28: 0.14
A29: Permanence | B29: ButtonUnmask | C29: MemER | D29: =IF(COUNTA('Per-Episode'!$D$25:$BA$25)=0,"",COUNTIF('Per-Episode'!$D$25:$BA$25,"success")) | E29: =IF(COUNTA('Per-Episode'!$D$25:$BA$25)=0,"",COUNTIF('Per-Episode'!$D$25:$BA$25,"fail")) | F29: =IF(COUNTA('Per-Episode'!$D$25:$BA$25)=0,"",COUNTIF('Per-Episode'!$D$25:$BA$25,"timeout")) | G29: =IF(COUNTA('Per-Episode'!$D$25:$BA$25)=0,"",COUNTIF('Per-Episode'!$D$25:$BA$25,"scene_error")) | H29: =IF(COUNTA('Per-Episode'!$D$25:$BA$25)=0,"",COUNTA('Per-Episode'!$D$25:$BA$25)) | I29: =IF($H$29="","",$D$29/$H$29)
A30: Permanence | B30: ButtonUnmask | C30: 512 | D30: =IF(COUNTA('Per-Episode'!$D$26:$BA$26)=0,"",COUNTIF('Per-Episode'!$D$26:$BA$26,"success")) | E30: =IF(COUNTA('Per-Episode'!$D$26:$BA$26)=0,"",COUNTIF('Per-Episode'!$D$26:$BA$26,"fail")) | F30: =IF(COUNTA('Per-Episode'!$D$26:$BA$26)=0,"",COUNTIF('Per-Episode'!$D$26:$BA$26,"timeout")) | G30: =IF(COUNTA('Per-Episode'!$D$26:$BA$26)=0,"",COUNTIF('Per-Episode'!$D$26:$BA$26,"scene_error")) | H30: =IF(COUNTA('Per-Episode'!$D$26:$BA$26)=0,"",COUNTA('Per-Episode'!$D$26:$BA$26)) | I30: =IF($H$30="","",$D$30/$H$30)
A31: Permanence | B31: VideoUnmaskSwap | C31: hitsz | D31: =IF(COUNTA('Per-Episode'!$D$27:$BA$27)=0,"",COUNTIF('Per-Episode'!$D$27:$BA$27,"success")) | E31: =IF(COUNTA('Per-Episode'!$D$27:$BA$27)=0,"",COUNTIF('Per-Episode'!$D$27:$BA$27,"fail")) | F31: =IF(COUNTA('Per-Episode'!$D$27:$BA$27)=0,"",COUNTIF('Per-Episode'!$D$27:$BA$27,"timeout")) | G31: =IF(COUNTA('Per-Episode'!$D$27:$BA$27)=0,"",COUNTIF('Per-Episode'!$D$27:$BA$27,"scene_error")) | H31: =IF(COUNTA('Per-Episode'!$D$27:$BA$27)=0,"",COUNTA('Per-Episode'!$D$27:$BA$27)) | I31: =IF($H$31="","",$D$31/$H$31)
A32: Permanence | B32: VideoUnmaskSwap | C32: thu | D32: 9 | E32: 41 | F32: 0 | G32: 0 | H32: 50 | I32: 0.18
A33: Permanence | B33: VideoUnmaskSwap | C33: MemER | D33: =IF(COUNTA('Per-Episode'!$D$29:$BA$29)=0,"",COUNTIF('Per-Episode'!$D$29:$BA$29,"success")) | E33: =IF(COUNTA('Per-Episode'!$D$29:$BA$29)=0,"",COUNTIF('Per-Episode'!$D$29:$BA$29,"fail")) | F33: =IF(COUNTA('Per-Episode'!$D$29:$BA$29)=0,"",COUNTIF('Per-Episode'!$D$29:$BA$29,"timeout")) | G33: =IF(COUNTA('Per-Episode'!$D$29:$BA$29)=0,"",COUNTIF('Per-Episode'!$D$29:$BA$29,"scene_error")) | H33: =IF(COUNTA('Per-Episode'!$D$29:$BA$29)=0,"",COUNTA('Per-Episode'!$D$29:$BA$29)) | I33: =IF($H$33="","",$D$33/$H$33)
A34: Permanence | B34: VideoUnmaskSwap | C34: 512 | D34: =IF(COUNTA('Per-Episode'!$D$30:$BA$30)=0,"",COUNTIF('Per-Episode'!$D$30:$BA$30,"success")) | E34: =IF(COUNTA('Per-Episode'!$D$30:$BA$30)=0,"",COUNTIF('Per-Episode'!$D$30:$BA$30,"fail")) | F34: =IF(COUNTA('Per-Episode'!$D$30:$BA$30)=0,"",COUNTIF('Per-Episode'!$D$30:$BA$30,"timeout")) | G34: =IF(COUNTA('Per-Episode'!$D$30:$BA$30)=0,"",COUNTIF('Per-Episode'!$D$30:$BA$30,"scene_error")) | H34: =IF(COUNTA('Per-Episode'!$D$30:$BA$30)=0,"",COUNTA('Per-Episode'!$D$30:$BA$30)) | I34: =IF($H$34="","",$D$34/$H$34)
A35: Permanence | B35: ButtonUnmaskSwap | C35: hitsz | D35: =IF(COUNTA('Per-Episode'!$D$31:$BA$31)=0,"",COUNTIF('Per-Episode'!$D$31:$BA$31,"success")) | E35: =IF(COUNTA('Per-Episode'!$D$31:$BA$31)=0,"",COUNTIF('Per-Episode'!$D$31:$BA$31,"fail")) | F35: =IF(COUNTA('Per-Episode'!$D$31:$BA$31)=0,"",COUNTIF('Per-Episode'!$D$31:$BA$31,"timeout")) | G35: =IF(COUNTA('Per-Episode'!$D$31:$BA$31)=0,"",COUNTIF('Per-Episode'!$D$31:$BA$31,"scene_error")) | H35: =IF(COUNTA('Per-Episode'!$D$31:$BA$31)=0,"",COUNTA('Per-Episode'!$D$31:$BA$31)) | I35: =IF($H$35="","",$D$35/$H$35)
A36: Permanence | B36: ButtonUnmaskSwap | C36: thu | D36: 10 | E36: 33 | F36: 7 | G36: 0 | H36: 50 | I36: 0.2
A37: Permanence | B37: ButtonUnmaskSwap | C37: MemER | D37: =IF(COUNTA('Per-Episode'!$D$33:$BA$33)=0,"",COUNTIF('Per-Episode'!$D$33:$BA$33,"success")) | E37: =IF(COUNTA('Per-Episode'!$D$33:$BA$33)=0,"",COUNTIF('Per-Episode'!$D$33:$BA$33,"fail")) | F37: =IF(COUNTA('Per-Episode'!$D$33:$BA$33)=0,"",COUNTIF('Per-Episode'!$D$33:$BA$33,"timeout")) | G37: =IF(COUNTA('Per-Episode'!$D$33:$BA$33)=0,"",COUNTIF('Per-Episode'!$D$33:$BA$33,"scene_error")) | H37: =IF(COUNTA('Per-Episode'!$D$33:$BA$33)=0,"",COUNTA('Per-Episode'!$D$33:$BA$33)) | I37: =IF($H$37="","",$D$37/$H$37)
A38: Permanence | B38: ButtonUnmaskSwap | C38: 512 | D38: =IF(COUNTA('Per-Episode'!$D$34:$BA$34)=0,"",COUNTIF('Per-Episode'!$D$34:$BA$34,"success")) | E38: =IF(COUNTA('Per-Episode'!$D$34:$BA$34)=0,"",COUNTIF('Per-Episode'!$D$34:$BA$34,"fail")) | F38: =IF(COUNTA('Per-Episode'!$D$34:$BA$34)=0,"",COUNTIF('Per-Episode'!$D$34:$BA$34,"timeout")) | G38: =IF(COUNTA('Per-Episode'!$D$34:$BA$34)=0,"",COUNTIF('Per-Episode'!$D$34:$BA$34,"scene_error")) | H38: =IF(COUNTA('Per-Episode'!$D$34:$BA$34)=0,"",COUNTA('Per-Episode'!$D$34:$BA$34)) | I38: =IF($H$38="","",$D$38/$H$38)
A39: Permanence — Subtotal | C39: hitsz | D39: =IF(SUM($H$23,$H$27,$H$31,$H$35)=0,"",SUM($D$23,$D$27,$D$31,$D$35)) | E39: =IF(SUM($H$23,$H$27,$H$31,$H$35)=0,"",SUM($E$23,$E$27,$E$31,$E$35)) | F39: =IF(SUM($H$23,$H$27,$H$31,$H$35)=0,"",SUM($F$23,$F$27,$F$31,$F$35)) | G39: =IF(SUM($H$23,$H$27,$H$31,$H$35)=0,"",SUM($G$23,$G$27,$G$31,$G$35)) | H39: =IF(SUM($H$23,$H$27,$H$31,$H$35)=0,"",SUM($H$23,$H$27,$H$31,$H$35)) | I39: =IF($H$39="","",$D$39/$H$39)
A40: Permanence — Subtotal | C40: thu | D40: 36 | E40: 154 | F40: 10 | G40: 0 | H40: 200 | I40: 0.18
...
